<?xml version ='1.0'?>
<!-- Author: Eech Hsiao -->
<!-- hsiaoy4@mcmaster.ca -->

<robot name = "robot" xmlns:xacro = "http://www.ros.org/wiki/xacro">

    <xacro:include filename = "$(find macbot_description)/urdf/material.xacro"/>
    <xacro:include filename = "$(find macbot_description)/urdf/robot_textureless.gazebo"/>


    <xacro:property name = "mirror_caster_x"    value = "0.075"     />
    <xacro:property name = "mirror_caster_y"    value = "0.075"     />
    <xacro:property name = "mirror_caster_z"    value = "0.094"     />
    <xacro:property name = "caster_radius"      value = "0.0185"    />
    <xacro:property name = "caster_thickness"   value = "0.02"      />
    

    <xacro:property name = "mirror_wheel_x"     value = "0.075"     />
    <xacro:property name = "mirror_wheel_y"     value = "0.1"       />
    <xacro:property name = "mirror_wheel_z"     value = "0.079"     />
    <xacro:property name = "wheel_radius"       value = "0.0325"    />
    <xacro:property name = "wheel_thickness"    value = "0.025"     />


    <!-- 
    <xacro:include filename="$(find mybot_description)/urdf/macros.xacro" /> -->

    <!-- 0.3 (wide) // 0.322 (long) // 0.188 (height)-->
    <!-- 0.065 (wheel diameter) -->
    <!-- 0.037 (caster diameter) -->

    <!-- LEFT and RIGHT designations taken from POV of Robot -->

    <!-- CHASSIS -->
    <link name = 'base_link'>
        <!-- Giving a little height off the Z axis -->
        <pose>0 0 0.1 0 0 0</pose>

        <inertial>
            <mass value = "15" />       <!-- 20 kgs (arbitrary) -->
            <origin xyz = "0 0 0.1" rpy = "0 0 0" />
            <inertia
                ixx="0.1" ixy="0" ixz="0"
                iyy="0.1" iyz="0"
                izz="0.1"/>
        </inertial>

        <!-- BODY -->
        <collision name = 'base_link_collision'>
            <geometry>
                <box size = "0.3 0.322 0.188"/>
            </geometry>
        </collision>

        <visual name = 'base_link_visual'>
            <origin xyz = "0 0 0" rpy = "0 0 0"/>
            <geometry>
                <box size = "0.3 0.322 0.188"/>
            </geometry>
            <material name = "green"/>
        </visual>

        <!-- LEFT CASTER -->
        <collision name = 'left_caster_collision'>
            <origin xyz ="-${mirror_caster_x} ${mirror_caster_y} -${mirror_caster_z}" rpy = "0 1.5707 1.5707"/>
            <geometry>
                <cylinder radius = "${caster_radius}" length = "${caster_thickness}"/>
            </geometry>

            <surface>
                <friction>
                    <ode>
                        <mu>0</mu>
                        <mu2>0</mu2>
                        <slip1>1.0</slip1>
                        <slip2>1.0</slip2>
                    </ode>
                </friction>
            </surface>
        </collision>

        <visual name = 'left_caster_visual'>
            <origin xyz ="-${mirror_caster_x} ${mirror_caster_y} -${mirror_caster_z}" rpy = "0 1.5707 1.5707"/>
            <geometry>
                <cylinder radius = "${caster_radius}" length = "${caster_thickness}"/>
            </geometry>
            <material name = "magenta"/>
        </visual>

        <!-- RIGHT CASTER -->
        <collision name = 'right_caster_collision'>
            <origin xyz ="-${mirror_caster_x} -${mirror_caster_y} -${mirror_caster_z}" rpy = "0 1.5707 1.5707"/>
            <geometry>
                <cylinder radius = "${caster_radius}" length = "${caster_thickness}"/>
            </geometry>

            <surface>
                <friction>
                    <ode>
                        <mu>0</mu>
                        <mu2>0</mu2>
                        <slip1>1.0</slip1>
                        <slip2>1.0</slip2>
                    </ode>
                </friction>
            </surface>
        </collision>

        <visual name = 'right_caster_visual'>
            <origin xyz ="-${mirror_caster_x} -${mirror_caster_y} -${mirror_caster_z}" rpy = "0 1.5707 1.5707"/>
            <geometry>
                <cylinder radius = "${caster_radius}" length = "${caster_thickness}"/>
            </geometry>
            <material name = "magenta"/>
        </visual>
    </link>
    
    <!-- LEFT WHEEL -->
    <link name = "left_wheel">
        <inertial>
            <mass value = "10" /> 
            <origin xyz = "0 0 0" rpy = "0 0 0" />
            <inertia
                ixx = "0.1" ixy = "0" ixz = "0"
                iyy = "0.1" iyz = "0"
                izz = "0.1"/>
        </inertial>

        <collision name = "left_wheel_collision">
            <origin xyz = "0 0 0" rpy = "0 1.5707 1.5707"/>
            <geometry>
                <cylinder radius = "${wheel_radius}" length = "${wheel_thickness}"/>
             </geometry>
        </collision>

        <visual name = "left_wheel_visual">
            <origin xyz = "0 0 0" rpy = "0 1.5707 1.5707"/>
            <geometry>
                <cylinder radius = "${wheel_radius}" length = "${wheel_thickness}"/>
            </geometry>
        </visual>
    </link>

    <!-- RIGHT WHEEL -->
    <link name = "right_wheel">
        <inertial>
            <mass value = "10" /> 
            <origin xyz = "0 0 0" rpy = "0 0 0" />
            <inertia
                ixx = "0.1" ixy = "0" ixz = "0"
                iyy = "0.1" iyz = "0"
                izz = "0.1"/>
        </inertial>

        <collision name = "right_wheel_collision">
            <origin xyz = "0 0 0" rpy = "0 1.5707 1.5707"/>
            <geometry>
                <cylinder radius = "${wheel_radius}" length = "${wheel_thickness}"/>
             </geometry>
        </collision>

        <visual name = "right_wheel_visual">
            <origin xyz = "0 0 0" rpy = "0 1.5707 1.5707"/>
            <geometry>
                <cylinder radius = "${wheel_radius}" length = "${wheel_thickness}"/>
            </geometry>
        </visual>
    </link>

    <joint type = "continuous" name = "left_wheel_hinge">
        <origin xyz = "${mirror_wheel_x} ${mirror_wheel_y} -${mirror_wheel_z}" rpy = "0 0 0"/>
        <child link = "left_wheel"/>
        <parent link = "base_link"/>
        <axis xyz = "0 1 0" rpy = "0 0 0"/>
        <limit effort = "10000" velocity = "1000"/>
        <joint_properties damping = "1.0" friction = "1.0"/>
    </joint>

    <joint type = "continuous" name = "right_wheel_hinge">
        <origin xyz = "${mirror_wheel_x} -${mirror_wheel_y} -${mirror_wheel_z}" rpy = "0 0 0"/>
        <child link = "right_wheel"/>
        <parent link = "base_link"/>
        <axis xyz = "0 1 0" rpy = "0 0 0"/>
        <limit effort = "10000" velocity = "1000"/>
        <joint_properties damping = "1.0" friction = "1"/>
    </joint>
</robot>